Traceback (most recent call last):
  File "/usr/local/Caskroom/miniconda/base/envs/jupyterbook/lib/python3.10/site-packages/jupyter_cache/executors/utils.py", line 58, in single_nb_execution
    executenb(
  File "/usr/local/Caskroom/miniconda/base/envs/jupyterbook/lib/python3.10/site-packages/nbclient/client.py", line 1314, in execute
    return NotebookClient(nb=nb, resources=resources, km=km, **kwargs).execute()
  File "/usr/local/Caskroom/miniconda/base/envs/jupyterbook/lib/python3.10/site-packages/jupyter_core/utils/__init__.py", line 165, in wrapped
    return loop.run_until_complete(inner)
  File "/usr/local/Caskroom/miniconda/base/envs/jupyterbook/lib/python3.10/asyncio/base_events.py", line 649, in run_until_complete
    return future.result()
  File "/usr/local/Caskroom/miniconda/base/envs/jupyterbook/lib/python3.10/site-packages/nbclient/client.py", line 709, in async_execute
    await self.async_execute_cell(
  File "/usr/local/Caskroom/miniconda/base/envs/jupyterbook/lib/python3.10/site-packages/nbclient/client.py", line 1062, in async_execute_cell
    await self._check_raise_for_error(cell, cell_index, exec_reply)
  File "/usr/local/Caskroom/miniconda/base/envs/jupyterbook/lib/python3.10/site-packages/nbclient/client.py", line 918, in _check_raise_for_error
    raise CellExecutionError.from_cell_and_msg(cell, exec_reply_content)
nbclient.exceptions.CellExecutionError: An error occurred while executing the following cell:
------------------
import dash
from dash import dcc, html
from dash.dependencies import Input, Output
import plotly.graph_objects as go
import pandas as pd

df = pd.read_csv("Treatment.csv")
df_transposed = df.set_index('Country').transpose()

app1 = dash.Dash(__name__)

app1.layout = html.Div([
    dcc.Dropdown(
        id='country-select',
        options=[{'label': country, 'value': country} for country in df['Country'].unique()],
        value=['Portugal'], 
        multi=True  
    ),
    dcc.Graph(id='line-chart')
])

@app1.callback(
    Output('line-chart', 'figure'),
    [Input('country-select', 'value')]
)
def update_chart(selected_countries):
    fig = go.Figure()
    for country in selected_countries:
        fig.add_trace(go.Scatter(
            x=df_transposed.index, 
            y=df_transposed[country], 
            mode='lines+markers', 
            name=country
        ))

    fig.update_layout(
        title="Data from 2013 to 2021",
        xaxis_title="Year",
        yaxis_title="Value"
    )
    
    return fig

if __name__ == '__main__':
    app1.run_server(debug=True, port=8053)
------------------


[0;31m---------------------------------------------------------------------------[0m
[0;31mModuleNotFoundError[0m                       Traceback (most recent call last)
Cell [0;32mIn[3], line 1[0m
[0;32m----> 1[0m [38;5;28;01mimport[39;00m [38;5;21;01mdash[39;00m
[1;32m      2[0m [38;5;28;01mfrom[39;00m [38;5;21;01mdash[39;00m [38;5;28;01mimport[39;00m dcc, html
[1;32m      3[0m [38;5;28;01mfrom[39;00m [38;5;21;01mdash[39;00m[38;5;21;01m.[39;00m[38;5;21;01mdependencies[39;00m [38;5;28;01mimport[39;00m Input, Output

[0;31mModuleNotFoundError[0m: No module named 'dash'

